<?xml version="1.0" ?>
<robot name="robot">
  <!-- Base Link -->
  <link name="base_link">
    <visual>
      <geometry>
        <cylinder length="0" radius="0.05"/>
      </geometry>
    </visual>
  </link>

  <!-- Joint for Base Rotation -->
  <joint name="base_rotation" type="continuous">
    <parent link="world"/>
    <child link="base_link"/>
    <origin xyz="0 0 0" rpy="0 0 0"/>
    <axis xyz="1 0 0"/>
  </joint>

  <!-- Link and Joint for First Arm Segment -->
  <link name="link1">
    <visual>
      <geometry>
        <cylinder length="0.05" radius="0.05"/>
      </geometry>
    </visual>
  </link>
  <joint name="joint1" type="revolute">
    <parent link="base_link"/>
    <child link="link1"/>
    <origin xyz="0 0 0.05" rpy="0 0 0"/>
    <axis xyz="1 0 0"/>
  </joint>

  <!-- Link and Joint for Second Arm Segment -->
  <link name="link2">
    <visual>
      <geometry>
        <cylinder length="0.05" radius="0.05"/>
      </geometry>
    </visual>
  </link>
  <joint name="joint2" type="revolute">
    <parent link="link1"/>
    <child link="link2"/>
    <origin xyz="0 0 0.05" rpy="0 0 0"/>
    <axis xyz="1 0 0"/>
  </joint>

  <!-- Link and Joint for Third Arm Segment -->
  <link name="link3">
    <visual>
      <geometry>
        <cylinder length="0.05" radius="0.05"/>
      </geometry>
    </visual>
  </link>
  <joint name="joint3" type="revolute">
    <parent link="link2"/>
    <child link="link3"/>
    <origin xyz="0 0 0.05" rpy="0 0 0"/>
    <axis xyz="0 0 0"/>
  </joint>

</robot>
